[2024-06-02T15:29:44.698+0000] {local_task_job_runner.py:120} INFO - ::group::Pre task execution logs
[2024-06-02T15:29:44.713+0000] {taskinstance.py:2076} INFO - Dependencies all met for dep_context=non-requeueable deps ti=<TaskInstance: api_to_redshift.load_data_task manual__2024-06-02T15:29:33.480697+00:00 [queued]>
[2024-06-02T15:29:44.720+0000] {taskinstance.py:2076} INFO - Dependencies all met for dep_context=requeueable deps ti=<TaskInstance: api_to_redshift.load_data_task manual__2024-06-02T15:29:33.480697+00:00 [queued]>
[2024-06-02T15:29:44.721+0000] {taskinstance.py:2306} INFO - Starting attempt 1 of 1
[2024-06-02T15:29:44.731+0000] {taskinstance.py:2330} INFO - Executing <Task(BashOperator): load_data_task> on 2024-06-02 15:29:33.480697+00:00
[2024-06-02T15:29:44.757+0000] {warnings.py:110} WARNING - /home/***/.local/lib/python3.12/site-packages/***/task/task_runner/standard_task_runner.py:61: DeprecationWarning: This process (pid=76) is multi-threaded, use of fork() may lead to deadlocks in the child.
  pid = os.fork()

[2024-06-02T15:29:44.760+0000] {standard_task_runner.py:63} INFO - Started process 78 to run task
[2024-06-02T15:29:44.759+0000] {standard_task_runner.py:90} INFO - Running: ['***', 'tasks', 'run', 'api_to_redshift', 'load_data_task', 'manual__2024-06-02T15:29:33.480697+00:00', '--job-id', '273', '--raw', '--subdir', 'DAGS_FOLDER/get_data.py', '--cfg-path', '/tmp/tmpi4qb0s9j']
[2024-06-02T15:29:44.761+0000] {standard_task_runner.py:91} INFO - Job 273: Subtask load_data_task
[2024-06-02T15:29:44.816+0000] {task_command.py:426} INFO - Running <TaskInstance: api_to_redshift.load_data_task manual__2024-06-02T15:29:33.480697+00:00 [running]> on host c5a05770e503
[2024-06-02T15:29:44.895+0000] {taskinstance.py:2648} INFO - Exporting env vars: AIRFLOW_CTX_DAG_OWNER='Data Team' AIRFLOW_CTX_DAG_ID='api_to_redshift' AIRFLOW_CTX_TASK_ID='load_data_task' AIRFLOW_CTX_EXECUTION_DATE='2024-06-02T15:29:33.480697+00:00' AIRFLOW_CTX_TRY_NUMBER='1' AIRFLOW_CTX_DAG_RUN_ID='manual__2024-06-02T15:29:33.480697+00:00'
[2024-06-02T15:29:44.897+0000] {taskinstance.py:430} INFO - ::endgroup::
[2024-06-02T15:29:44.899+0000] {subprocess.py:63} INFO - Tmp dir root location: /tmp
[2024-06-02T15:29:44.900+0000] {subprocess.py:75} INFO - Running command: ['/usr/bin/bash', '-c', "curl 'http://s3-to-redshift-lambda:9500/2015-03-31/functions/function/invocations' -d '{}'"]
[2024-06-02T15:29:44.920+0000] {subprocess.py:86} INFO - Output:
[2024-06-02T15:29:44.960+0000] {subprocess.py:93} INFO -   % Total    % Received % Xferd  Average Speed   Time    Time     Time  Current
[2024-06-02T15:29:44.962+0000] {subprocess.py:93} INFO -                                  Dload  Upload   Total   Spent    Left  Speed
[2024-06-02T15:29:44.962+0000] {subprocess.py:93} INFO -   0     0    0     0    0     0      0      0 --:--:-- --:--:-- --:--:--     0  0     0    0     0    0     0      0      0 --:--:-- --:--:-- --:--:--     0
[2024-06-02T15:29:44.963+0000] {subprocess.py:93} INFO - curl: (7) Failed to connect to s3-to-redshift-lambda port 9500 after 1 ms: Couldn't connect to server
[2024-06-02T15:29:44.965+0000] {subprocess.py:97} INFO - Command exited with return code 7
[2024-06-02T15:29:44.967+0000] {taskinstance.py:441} INFO - ::group::Post task execution logs
[2024-06-02T15:29:44.981+0000] {taskinstance.py:2905} ERROR - Task failed with exception
Traceback (most recent call last):
  File "/home/airflow/.local/lib/python3.12/site-packages/airflow/models/taskinstance.py", line 465, in _execute_task
    result = _execute_callable(context=context, **execute_callable_kwargs)
             ^^^^^^^^^^^^^^^^^^^^^^^^^^^^^^^^^^^^^^^^^^^^^^^^^^^^^^^^^^^^^
  File "/home/airflow/.local/lib/python3.12/site-packages/airflow/models/taskinstance.py", line 432, in _execute_callable
    return execute_callable(context=context, **execute_callable_kwargs)
           ^^^^^^^^^^^^^^^^^^^^^^^^^^^^^^^^^^^^^^^^^^^^^^^^^^^^^^^^^^^^
  File "/home/airflow/.local/lib/python3.12/site-packages/airflow/models/baseoperator.py", line 400, in wrapper
    return func(self, *args, **kwargs)
           ^^^^^^^^^^^^^^^^^^^^^^^^^^^
  File "/home/airflow/.local/lib/python3.12/site-packages/airflow/operators/bash.py", line 243, in execute
    raise AirflowException(
airflow.exceptions.AirflowException: Bash command failed. The command returned a non-zero exit code 7.
[2024-06-02T15:29:44.989+0000] {taskinstance.py:1206} INFO - Marking task as FAILED. dag_id=api_to_redshift, task_id=load_data_task, run_id=manual__2024-06-02T15:29:33.480697+00:00, execution_date=20240602T152933, start_date=20240602T152944, end_date=20240602T152944
[2024-06-02T15:29:45.011+0000] {standard_task_runner.py:110} ERROR - Failed to execute job 273 for task load_data_task (Bash command failed. The command returned a non-zero exit code 7.; 78)
[2024-06-02T15:29:45.056+0000] {local_task_job_runner.py:240} INFO - Task exited with return code 1
[2024-06-02T15:29:45.077+0000] {taskinstance.py:3498} INFO - 0 downstream tasks scheduled from follow-on schedule check
[2024-06-02T15:29:45.080+0000] {local_task_job_runner.py:222} INFO - ::endgroup::
