[2024-06-02T12:42:16.681+0000] {local_task_job_runner.py:120} INFO - ::group::Pre task execution logs
[2024-06-02T12:42:16.693+0000] {taskinstance.py:2076} INFO - Dependencies all met for dep_context=non-requeueable deps ti=<TaskInstance: api_to_redshift.transformation_task manual__2024-06-02T12:42:11.930442+00:00 [queued]>
[2024-06-02T12:42:16.697+0000] {taskinstance.py:2076} INFO - Dependencies all met for dep_context=requeueable deps ti=<TaskInstance: api_to_redshift.transformation_task manual__2024-06-02T12:42:11.930442+00:00 [queued]>
[2024-06-02T12:42:16.698+0000] {taskinstance.py:2306} INFO - Starting attempt 1 of 1
[2024-06-02T12:42:16.704+0000] {taskinstance.py:2330} INFO - Executing <Task(BashOperator): transformation_task> on 2024-06-02 12:42:11.930442+00:00
[2024-06-02T12:42:16.709+0000] {warnings.py:110} WARNING - /home/***/.local/lib/python3.12/site-packages/***/task/task_runner/standard_task_runner.py:61: DeprecationWarning: This process (pid=430) is multi-threaded, use of fork() may lead to deadlocks in the child.
  pid = os.fork()

[2024-06-02T12:42:16.711+0000] {standard_task_runner.py:63} INFO - Started process 432 to run task
[2024-06-02T12:42:16.712+0000] {standard_task_runner.py:90} INFO - Running: ['***', 'tasks', 'run', 'api_to_redshift', 'transformation_task', 'manual__2024-06-02T12:42:11.930442+00:00', '--job-id', '239', '--raw', '--subdir', 'DAGS_FOLDER/get_data.py', '--cfg-path', '/tmp/tmpmn6ebw8s']
[2024-06-02T12:42:16.714+0000] {standard_task_runner.py:91} INFO - Job 239: Subtask transformation_task
[2024-06-02T12:42:16.752+0000] {task_command.py:426} INFO - Running <TaskInstance: api_to_redshift.transformation_task manual__2024-06-02T12:42:11.930442+00:00 [running]> on host 1d861f4bf9ce
[2024-06-02T12:42:16.806+0000] {taskinstance.py:2648} INFO - Exporting env vars: AIRFLOW_CTX_DAG_OWNER='Data Team' AIRFLOW_CTX_DAG_ID='api_to_redshift' AIRFLOW_CTX_TASK_ID='transformation_task' AIRFLOW_CTX_EXECUTION_DATE='2024-06-02T12:42:11.930442+00:00' AIRFLOW_CTX_TRY_NUMBER='1' AIRFLOW_CTX_DAG_RUN_ID='manual__2024-06-02T12:42:11.930442+00:00'
[2024-06-02T12:42:16.808+0000] {taskinstance.py:430} INFO - ::endgroup::
[2024-06-02T12:42:16.809+0000] {subprocess.py:63} INFO - Tmp dir root location: /tmp
[2024-06-02T12:42:16.809+0000] {subprocess.py:75} INFO - Running command: ['/usr/bin/bash', '-c', 'python glue_job.py']
[2024-06-02T12:42:16.819+0000] {subprocess.py:86} INFO - Output:
[2024-06-02T12:42:24.278+0000] {subprocess.py:93} INFO - Traceback (most recent call last):
[2024-06-02T12:42:24.280+0000] {subprocess.py:93} INFO -   File "/home/***/.local/lib/python3.12/site-packages/urllib3/connection.py", line 198, in _new_conn
[2024-06-02T12:42:24.282+0000] {subprocess.py:93} INFO -     sock = connection.create_connection(
[2024-06-02T12:42:24.283+0000] {subprocess.py:93} INFO -            ^^^^^^^^^^^^^^^^^^^^^^^^^^^^^
[2024-06-02T12:42:24.283+0000] {subprocess.py:93} INFO -   File "/home/***/.local/lib/python3.12/site-packages/urllib3/util/connection.py", line 85, in create_connection
[2024-06-02T12:42:24.284+0000] {subprocess.py:93} INFO -     raise err
[2024-06-02T12:42:24.286+0000] {subprocess.py:93} INFO -   File "/home/***/.local/lib/python3.12/site-packages/urllib3/util/connection.py", line 73, in create_connection
[2024-06-02T12:42:24.287+0000] {subprocess.py:93} INFO -     sock.connect(sa)
[2024-06-02T12:42:24.287+0000] {subprocess.py:93} INFO - ConnectionRefusedError: [Errno 111] Connection refused
[2024-06-02T12:42:24.288+0000] {subprocess.py:93} INFO - 
[2024-06-02T12:42:24.289+0000] {subprocess.py:93} INFO - The above exception was the direct cause of the following exception:
[2024-06-02T12:42:24.290+0000] {subprocess.py:93} INFO - 
[2024-06-02T12:42:24.291+0000] {subprocess.py:93} INFO - Traceback (most recent call last):
[2024-06-02T12:42:24.291+0000] {subprocess.py:93} INFO -   File "/home/***/.local/lib/python3.12/site-packages/botocore/httpsession.py", line 464, in send
[2024-06-02T12:42:24.292+0000] {subprocess.py:93} INFO -     urllib_response = conn.urlopen(
[2024-06-02T12:42:24.293+0000] {subprocess.py:93} INFO -                       ^^^^^^^^^^^^^
[2024-06-02T12:42:24.294+0000] {subprocess.py:93} INFO -   File "/home/***/.local/lib/python3.12/site-packages/urllib3/connectionpool.py", line 847, in urlopen
[2024-06-02T12:42:24.295+0000] {subprocess.py:93} INFO -     retries = retries.increment(
[2024-06-02T12:42:24.296+0000] {subprocess.py:93} INFO -               ^^^^^^^^^^^^^^^^^^
[2024-06-02T12:42:24.296+0000] {subprocess.py:93} INFO -   File "/home/***/.local/lib/python3.12/site-packages/urllib3/util/retry.py", line 445, in increment
[2024-06-02T12:42:24.297+0000] {subprocess.py:93} INFO -     raise reraise(type(error), error, _stacktrace)
[2024-06-02T12:42:24.298+0000] {subprocess.py:93} INFO -           ^^^^^^^^^^^^^^^^^^^^^^^^^^^^^^^^^^^^^^^^
[2024-06-02T12:42:24.299+0000] {subprocess.py:93} INFO -   File "/home/***/.local/lib/python3.12/site-packages/urllib3/util/util.py", line 39, in reraise
[2024-06-02T12:42:24.299+0000] {subprocess.py:93} INFO -     raise value
[2024-06-02T12:42:24.300+0000] {subprocess.py:93} INFO -   File "/home/***/.local/lib/python3.12/site-packages/urllib3/connectionpool.py", line 793, in urlopen
[2024-06-02T12:42:24.301+0000] {subprocess.py:93} INFO -     response = self._make_request(
[2024-06-02T12:42:24.302+0000] {subprocess.py:93} INFO -                ^^^^^^^^^^^^^^^^^^^
[2024-06-02T12:42:24.302+0000] {subprocess.py:93} INFO -   File "/home/***/.local/lib/python3.12/site-packages/urllib3/connectionpool.py", line 496, in _make_request
[2024-06-02T12:42:24.303+0000] {subprocess.py:93} INFO -     conn.request(
[2024-06-02T12:42:24.304+0000] {subprocess.py:93} INFO -   File "/home/***/.local/lib/python3.12/site-packages/botocore/awsrequest.py", line 96, in request
[2024-06-02T12:42:24.305+0000] {subprocess.py:93} INFO -     rval = super().request(method, url, body, headers, *args, **kwargs)
[2024-06-02T12:42:24.305+0000] {subprocess.py:93} INFO -            ^^^^^^^^^^^^^^^^^^^^^^^^^^^^^^^^^^^^^^^^^^^^^^^^^^^^^^^^^^^^
[2024-06-02T12:42:24.306+0000] {subprocess.py:93} INFO -   File "/home/***/.local/lib/python3.12/site-packages/urllib3/connection.py", line 400, in request
[2024-06-02T12:42:24.307+0000] {subprocess.py:93} INFO -     self.endheaders()
[2024-06-02T12:42:24.308+0000] {subprocess.py:93} INFO -   File "/usr/local/lib/python3.12/http/client.py", line 1331, in endheaders
[2024-06-02T12:42:24.308+0000] {subprocess.py:93} INFO -     self._send_output(message_body, encode_chunked=encode_chunked)
[2024-06-02T12:42:24.309+0000] {subprocess.py:93} INFO -   File "/home/***/.local/lib/python3.12/site-packages/botocore/awsrequest.py", line 123, in _send_output
[2024-06-02T12:42:24.310+0000] {subprocess.py:93} INFO -     self.send(msg)
[2024-06-02T12:42:24.311+0000] {subprocess.py:93} INFO -   File "/home/***/.local/lib/python3.12/site-packages/botocore/awsrequest.py", line 223, in send
[2024-06-02T12:42:24.312+0000] {subprocess.py:93} INFO -     return super().send(str)
[2024-06-02T12:42:24.312+0000] {subprocess.py:93} INFO -            ^^^^^^^^^^^^^^^^^
[2024-06-02T12:42:24.313+0000] {subprocess.py:93} INFO -   File "/usr/local/lib/python3.12/http/client.py", line 1035, in send
[2024-06-02T12:42:24.314+0000] {subprocess.py:93} INFO -     self.connect()
[2024-06-02T12:42:24.315+0000] {subprocess.py:93} INFO -   File "/home/***/.local/lib/python3.12/site-packages/urllib3/connection.py", line 238, in connect
[2024-06-02T12:42:24.317+0000] {subprocess.py:93} INFO -     self.sock = self._new_conn()
[2024-06-02T12:42:24.318+0000] {subprocess.py:93} INFO -                 ^^^^^^^^^^^^^^^^
[2024-06-02T12:42:24.319+0000] {subprocess.py:93} INFO -   File "/home/***/.local/lib/python3.12/site-packages/urllib3/connection.py", line 213, in _new_conn
[2024-06-02T12:42:24.320+0000] {subprocess.py:93} INFO -     raise NewConnectionError(
[2024-06-02T12:42:24.321+0000] {subprocess.py:93} INFO - urllib3.exceptions.NewConnectionError: <botocore.awsrequest.AWSHTTPConnection object at 0xffff8d6baff0>: Failed to establish a new connection: [Errno 111] Connection refused
[2024-06-02T12:42:24.321+0000] {subprocess.py:93} INFO - 
[2024-06-02T12:42:24.323+0000] {subprocess.py:93} INFO - During handling of the above exception, another exception occurred:
[2024-06-02T12:42:24.323+0000] {subprocess.py:93} INFO - 
[2024-06-02T12:42:24.324+0000] {subprocess.py:93} INFO - Traceback (most recent call last):
[2024-06-02T12:42:24.326+0000] {subprocess.py:93} INFO -   File "/opt/***/scripts/glue_job.py", line 34, in <module>
[2024-06-02T12:42:24.327+0000] {subprocess.py:93} INFO -     response = s3_client.get_object(Bucket=bucket_name, Key=file)
[2024-06-02T12:42:24.328+0000] {subprocess.py:93} INFO -                ^^^^^^^^^^^^^^^^^^^^^^^^^^^^^^^^^^^^^^^^^^^^^^^^^^
[2024-06-02T12:42:24.328+0000] {subprocess.py:93} INFO -   File "/home/***/.local/lib/python3.12/site-packages/botocore/client.py", line 553, in _api_call
[2024-06-02T12:42:24.329+0000] {subprocess.py:93} INFO -     return self._make_api_call(operation_name, kwargs)
[2024-06-02T12:42:24.329+0000] {subprocess.py:93} INFO -            ^^^^^^^^^^^^^^^^^^^^^^^^^^^^^^^^^^^^^^^^^^^
[2024-06-02T12:42:24.330+0000] {subprocess.py:93} INFO -   File "/home/***/.local/lib/python3.12/site-packages/botocore/client.py", line 989, in _make_api_call
[2024-06-02T12:42:24.331+0000] {subprocess.py:93} INFO -     http, parsed_response = self._make_request(
[2024-06-02T12:42:24.331+0000] {subprocess.py:93} INFO -                             ^^^^^^^^^^^^^^^^^^^
[2024-06-02T12:42:24.332+0000] {subprocess.py:93} INFO -   File "/home/***/.local/lib/python3.12/site-packages/botocore/client.py", line 1015, in _make_request
[2024-06-02T12:42:24.332+0000] {subprocess.py:93} INFO -     return self._endpoint.make_request(operation_model, request_dict)
[2024-06-02T12:42:24.333+0000] {subprocess.py:93} INFO -            ^^^^^^^^^^^^^^^^^^^^^^^^^^^^^^^^^^^^^^^^^^^^^^^^^^^^^^^^^^
[2024-06-02T12:42:24.333+0000] {subprocess.py:93} INFO -   File "/home/***/.local/lib/python3.12/site-packages/botocore/endpoint.py", line 119, in make_request
[2024-06-02T12:42:24.334+0000] {subprocess.py:93} INFO -     return self._send_request(request_dict, operation_model)
[2024-06-02T12:42:24.334+0000] {subprocess.py:93} INFO -            ^^^^^^^^^^^^^^^^^^^^^^^^^^^^^^^^^^^^^^^^^^^^^^^^^
[2024-06-02T12:42:24.335+0000] {subprocess.py:93} INFO -   File "/home/***/.local/lib/python3.12/site-packages/botocore/endpoint.py", line 202, in _send_request
[2024-06-02T12:42:24.335+0000] {subprocess.py:93} INFO -     while self._needs_retry(
[2024-06-02T12:42:24.336+0000] {subprocess.py:93} INFO -           ^^^^^^^^^^^^^^^^^^
[2024-06-02T12:42:24.336+0000] {subprocess.py:93} INFO -   File "/home/***/.local/lib/python3.12/site-packages/botocore/endpoint.py", line 354, in _needs_retry
[2024-06-02T12:42:24.337+0000] {subprocess.py:93} INFO -     responses = self._event_emitter.emit(
[2024-06-02T12:42:24.337+0000] {subprocess.py:93} INFO -                 ^^^^^^^^^^^^^^^^^^^^^^^^^
[2024-06-02T12:42:24.338+0000] {subprocess.py:93} INFO -   File "/home/***/.local/lib/python3.12/site-packages/botocore/hooks.py", line 412, in emit
[2024-06-02T12:42:24.338+0000] {subprocess.py:93} INFO -     return self._emitter.emit(aliased_event_name, **kwargs)
[2024-06-02T12:42:24.339+0000] {subprocess.py:93} INFO -            ^^^^^^^^^^^^^^^^^^^^^^^^^^^^^^^^^^^^^^^^^^^^^^^^
[2024-06-02T12:42:24.339+0000] {subprocess.py:93} INFO -   File "/home/***/.local/lib/python3.12/site-packages/botocore/hooks.py", line 256, in emit
[2024-06-02T12:42:24.340+0000] {subprocess.py:93} INFO -     return self._emit(event_name, kwargs)
[2024-06-02T12:42:24.340+0000] {subprocess.py:93} INFO -            ^^^^^^^^^^^^^^^^^^^^^^^^^^^^^^
[2024-06-02T12:42:24.340+0000] {subprocess.py:93} INFO -   File "/home/***/.local/lib/python3.12/site-packages/botocore/hooks.py", line 239, in _emit
[2024-06-02T12:42:24.341+0000] {subprocess.py:93} INFO -     response = handler(**kwargs)
[2024-06-02T12:42:24.341+0000] {subprocess.py:93} INFO -                ^^^^^^^^^^^^^^^^^
[2024-06-02T12:42:24.342+0000] {subprocess.py:93} INFO -   File "/home/***/.local/lib/python3.12/site-packages/botocore/retryhandler.py", line 207, in __call__
[2024-06-02T12:42:24.343+0000] {subprocess.py:93} INFO -     if self._checker(**checker_kwargs):
[2024-06-02T12:42:24.343+0000] {subprocess.py:93} INFO -        ^^^^^^^^^^^^^^^^^^^^^^^^^^^^^^^
[2024-06-02T12:42:24.344+0000] {subprocess.py:93} INFO -   File "/home/***/.local/lib/python3.12/site-packages/botocore/retryhandler.py", line 284, in __call__
[2024-06-02T12:42:24.344+0000] {subprocess.py:93} INFO -     should_retry = self._should_retry(
[2024-06-02T12:42:24.345+0000] {subprocess.py:93} INFO -                    ^^^^^^^^^^^^^^^^^^^
[2024-06-02T12:42:24.345+0000] {subprocess.py:93} INFO -   File "/home/***/.local/lib/python3.12/site-packages/botocore/retryhandler.py", line 320, in _should_retry
[2024-06-02T12:42:24.346+0000] {subprocess.py:93} INFO -     return self._checker(attempt_number, response, caught_exception)
[2024-06-02T12:42:24.346+0000] {subprocess.py:93} INFO -            ^^^^^^^^^^^^^^^^^^^^^^^^^^^^^^^^^^^^^^^^^^^^^^^^^^^^^^^^^
[2024-06-02T12:42:24.347+0000] {subprocess.py:93} INFO -   File "/home/***/.local/lib/python3.12/site-packages/botocore/retryhandler.py", line 363, in __call__
[2024-06-02T12:42:24.347+0000] {subprocess.py:93} INFO -     checker_response = checker(
[2024-06-02T12:42:24.347+0000] {subprocess.py:93} INFO -                        ^^^^^^^^
[2024-06-02T12:42:24.348+0000] {subprocess.py:93} INFO -   File "/home/***/.local/lib/python3.12/site-packages/botocore/retryhandler.py", line 247, in __call__
[2024-06-02T12:42:24.349+0000] {subprocess.py:93} INFO -     return self._check_caught_exception(
[2024-06-02T12:42:24.349+0000] {subprocess.py:93} INFO -            ^^^^^^^^^^^^^^^^^^^^^^^^^^^^^
[2024-06-02T12:42:24.349+0000] {subprocess.py:93} INFO -   File "/home/***/.local/lib/python3.12/site-packages/botocore/retryhandler.py", line 416, in _check_caught_exception
[2024-06-02T12:42:24.350+0000] {subprocess.py:93} INFO -     raise caught_exception
[2024-06-02T12:42:24.350+0000] {subprocess.py:93} INFO -   File "/home/***/.local/lib/python3.12/site-packages/botocore/endpoint.py", line 281, in _do_get_response
[2024-06-02T12:42:24.351+0000] {subprocess.py:93} INFO -     http_response = self._send(request)
[2024-06-02T12:42:24.351+0000] {subprocess.py:93} INFO -                     ^^^^^^^^^^^^^^^^^^^
[2024-06-02T12:42:24.351+0000] {subprocess.py:93} INFO -   File "/home/***/.local/lib/python3.12/site-packages/botocore/endpoint.py", line 377, in _send
[2024-06-02T12:42:24.352+0000] {subprocess.py:93} INFO -     return self.http_session.send(request)
[2024-06-02T12:42:24.352+0000] {subprocess.py:93} INFO -            ^^^^^^^^^^^^^^^^^^^^^^^^^^^^^^^
[2024-06-02T12:42:24.353+0000] {subprocess.py:93} INFO -   File "/home/***/.local/lib/python3.12/site-packages/botocore/httpsession.py", line 493, in send
[2024-06-02T12:42:24.353+0000] {subprocess.py:93} INFO -     raise EndpointConnectionError(endpoint_url=request.url, error=e)
[2024-06-02T12:42:24.354+0000] {subprocess.py:93} INFO - botocore.exceptions.EndpointConnectionError: Could not connect to the endpoint URL: "http://localhost:6000/dream-data/raw_data.json"
[2024-06-02T12:42:24.404+0000] {subprocess.py:97} INFO - Command exited with return code 1
[2024-06-02T12:42:24.405+0000] {taskinstance.py:441} INFO - ::group::Post task execution logs
[2024-06-02T12:42:24.416+0000] {taskinstance.py:2905} ERROR - Task failed with exception
Traceback (most recent call last):
  File "/home/airflow/.local/lib/python3.12/site-packages/airflow/models/taskinstance.py", line 465, in _execute_task
    result = _execute_callable(context=context, **execute_callable_kwargs)
             ^^^^^^^^^^^^^^^^^^^^^^^^^^^^^^^^^^^^^^^^^^^^^^^^^^^^^^^^^^^^^
  File "/home/airflow/.local/lib/python3.12/site-packages/airflow/models/taskinstance.py", line 432, in _execute_callable
    return execute_callable(context=context, **execute_callable_kwargs)
           ^^^^^^^^^^^^^^^^^^^^^^^^^^^^^^^^^^^^^^^^^^^^^^^^^^^^^^^^^^^^
  File "/home/airflow/.local/lib/python3.12/site-packages/airflow/models/baseoperator.py", line 400, in wrapper
    return func(self, *args, **kwargs)
           ^^^^^^^^^^^^^^^^^^^^^^^^^^^
  File "/home/airflow/.local/lib/python3.12/site-packages/airflow/operators/bash.py", line 243, in execute
    raise AirflowException(
airflow.exceptions.AirflowException: Bash command failed. The command returned a non-zero exit code 1.
[2024-06-02T12:42:24.420+0000] {taskinstance.py:1206} INFO - Marking task as FAILED. dag_id=api_to_redshift, task_id=transformation_task, run_id=manual__2024-06-02T12:42:11.930442+00:00, execution_date=20240602T124211, start_date=20240602T124216, end_date=20240602T124224
[2024-06-02T12:42:24.429+0000] {standard_task_runner.py:110} ERROR - Failed to execute job 239 for task transformation_task (Bash command failed. The command returned a non-zero exit code 1.; 432)
[2024-06-02T12:42:24.458+0000] {local_task_job_runner.py:240} INFO - Task exited with return code 1
[2024-06-02T12:42:24.476+0000] {taskinstance.py:3498} INFO - 0 downstream tasks scheduled from follow-on schedule check
[2024-06-02T12:42:24.478+0000] {local_task_job_runner.py:222} INFO - ::endgroup::
