[2024-06-02T18:51:14.732+0000] {local_task_job_runner.py:120} INFO - ::group::Pre task execution logs
[2024-06-02T18:51:14.745+0000] {taskinstance.py:2076} INFO - Dependencies all met for dep_context=non-requeueable deps ti=<TaskInstance: api_to_redshift.load_data_task manual__2024-06-02T18:51:06.575783+00:00 [queued]>
[2024-06-02T18:51:14.749+0000] {taskinstance.py:2076} INFO - Dependencies all met for dep_context=requeueable deps ti=<TaskInstance: api_to_redshift.load_data_task manual__2024-06-02T18:51:06.575783+00:00 [queued]>
[2024-06-02T18:51:14.750+0000] {taskinstance.py:2306} INFO - Starting attempt 1 of 1
[2024-06-02T18:51:14.757+0000] {taskinstance.py:2330} INFO - Executing <Task(BashOperator): load_data_task> on 2024-06-02 18:51:06.575783+00:00
[2024-06-02T18:51:14.762+0000] {warnings.py:110} WARNING - /home/***/.local/lib/python3.12/site-packages/***/task/task_runner/standard_task_runner.py:61: DeprecationWarning: This process (pid=76) is multi-threaded, use of fork() may lead to deadlocks in the child.
  pid = os.fork()

[2024-06-02T18:51:14.764+0000] {standard_task_runner.py:63} INFO - Started process 85 to run task
[2024-06-02T18:51:14.764+0000] {standard_task_runner.py:90} INFO - Running: ['***', 'tasks', 'run', 'api_to_redshift', 'load_data_task', 'manual__2024-06-02T18:51:06.575783+00:00', '--job-id', '372', '--raw', '--subdir', 'DAGS_FOLDER/get_data.py', '--cfg-path', '/tmp/tmpd00pg3xw']
[2024-06-02T18:51:14.766+0000] {standard_task_runner.py:91} INFO - Job 372: Subtask load_data_task
[2024-06-02T18:51:14.808+0000] {task_command.py:426} INFO - Running <TaskInstance: api_to_redshift.load_data_task manual__2024-06-02T18:51:06.575783+00:00 [running]> on host 81659938f47a
[2024-06-02T18:51:14.880+0000] {taskinstance.py:2648} INFO - Exporting env vars: AIRFLOW_CTX_DAG_OWNER='Data Team' AIRFLOW_CTX_DAG_ID='api_to_redshift' AIRFLOW_CTX_TASK_ID='load_data_task' AIRFLOW_CTX_EXECUTION_DATE='2024-06-02T18:51:06.575783+00:00' AIRFLOW_CTX_TRY_NUMBER='1' AIRFLOW_CTX_DAG_RUN_ID='manual__2024-06-02T18:51:06.575783+00:00'
[2024-06-02T18:51:14.881+0000] {taskinstance.py:430} INFO - ::endgroup::
[2024-06-02T18:51:14.883+0000] {subprocess.py:63} INFO - Tmp dir root location: /tmp
[2024-06-02T18:51:14.884+0000] {subprocess.py:75} INFO - Running command: ['/usr/bin/bash', '-c', "curl 'http://s3-to-redshift-lambda:8080/2015-03-31/functions/function/invocations' -d '{}'"]
[2024-06-02T18:51:14.895+0000] {subprocess.py:86} INFO - Output:
[2024-06-02T18:51:14.904+0000] {subprocess.py:93} INFO -   % Total    % Received % Xferd  Average Speed   Time    Time     Time  Current
[2024-06-02T18:51:14.906+0000] {subprocess.py:93} INFO -                                  Dload  Upload   Total   Spent    Left  Speed
[2024-06-02T18:51:20.472+0000] {subprocess.py:93} INFO -   0     0    0     0    0     0      0      0 --:--:-- --:--:-- --:--:--     0100     2    0     0  100     2      0      1  0:00:02  0:00:01  0:00:01     1100     2    0     0    0     2      0      0 --:--:--  0:00:02 --:--:--     0100     2    0     0    0     2      0      0 --:--:--  0:00:03 --:--:--     0100     2    0     0    0     2      0      0 --:--:--  0:00:04 --:--:--     0100     2    0     0    0     2      0      0 --:--:--  0:00:05 --:--:--     0100  3151    0  3149    0     2    565      0 --:--:--  0:00:05 --:--:--   721100  3151    0  3149    0     2    565      0 --:--:--  0:00:05 --:--:--   935
[2024-06-02T18:51:20.477+0000] {subprocess.py:93} INFO - {"errorMessage": "Could not connect to the endpoint URL: \"http://localhost:6000/target/data.parquet\"", "errorType": "EndpointConnectionError", "requestId": "eb7ee514-2cee-49d2-838c-b47e78b4d68c", "stackTrace": ["  File \"/var/task/lambda_function.py\", line 61, in lambda_handler\n    df = get_source_data()\n", "  File \"/var/task/lambda_function.py\", line 27, in get_source_data\n    response = s3_client.get_object(Bucket=source_bucket, Key=file_key)\n", "  File \"/var/lang/lib/python3.12/site-packages/botocore/client.py\", line 553, in _api_call\n    return self._make_api_call(operation_name, kwargs)\n", "  File \"/var/lang/lib/python3.12/site-packages/botocore/client.py\", line 989, in _make_api_call\n    http, parsed_response = self._make_request(\n", "  File \"/var/lang/lib/python3.12/site-packages/botocore/client.py\", line 1015, in _make_request\n    return self._endpoint.make_request(operation_model, request_dict)\n", "  File \"/var/lang/lib/python3.12/site-packages/botocore/endpoint.py\", line 119, in make_request\n    return self._send_request(request_dict, operation_model)\n", "  File \"/var/lang/lib/python3.12/site-packages/botocore/endpoint.py\", line 202, in _send_request\n    while self._needs_retry(\n", "  File \"/var/lang/lib/python3.12/site-packages/botocore/endpoint.py\", line 354, in _needs_retry\n    responses = self._event_emitter.emit(\n", "  File \"/var/lang/lib/python3.12/site-packages/botocore/hooks.py\", line 412, in emit\n    return self._emitter.emit(aliased_event_name, **kwargs)\n", "  File \"/var/lang/lib/python3.12/site-packages/botocore/hooks.py\", line 256, in emit\n    return self._emit(event_name, kwargs)\n", "  File \"/var/lang/lib/python3.12/site-packages/botocore/hooks.py\", line 239, in _emit\n    response = handler(**kwargs)\n", "  File \"/var/lang/lib/python3.12/site-packages/botocore/retryhandler.py\", line 207, in __call__\n    if self._checker(**checker_kwargs):\n", "  File \"/var/lang/lib/python3.12/site-packages/botocore/retryhandler.py\", line 284, in __call__\n    should_retry = self._should_retry(\n", "  File \"/var/lang/lib/python3.12/site-packages/botocore/retryhandler.py\", line 320, in _should_retry\n    return self._checker(attempt_number, response, caught_exception)\n", "  File \"/var/lang/lib/python3.12/site-packages/botocore/retryhandler.py\", line 363, in __call__\n    checker_response = checker(\n", "  File \"/var/lang/lib/python3.12/site-packages/botocore/retryhandler.py\", line 247, in __call__\n    return self._check_caught_exception(\n", "  File \"/var/lang/lib/python3.12/site-packages/botocore/retryhandler.py\", line 416, in _check_caught_exception\n    raise caught_exception\n", "  File \"/var/lang/lib/python3.12/site-packages/botocore/endpoint.py\", line 281, in _do_get_response\n    http_response = self._send(request)\n", "  File \"/var/lang/lib/python3.12/site-packages/botocore/endpoint.py\", line 377, in _send\n    return self.http_session.send(request)\n", "  File \"/var/lang/lib/python3.12/site-packages/botocore/httpsession.py\", line 493, in send\n    raise EndpointConnectionError(endpoint_url=request.url, error=e)\n"]}
[2024-06-02T18:51:20.479+0000] {subprocess.py:97} INFO - Command exited with return code 0
[2024-06-02T18:51:20.482+0000] {taskinstance.py:441} INFO - ::group::Post task execution logs
[2024-06-02T18:51:20.515+0000] {taskinstance.py:1206} INFO - Marking task as SUCCESS. dag_id=api_to_redshift, task_id=load_data_task, run_id=manual__2024-06-02T18:51:06.575783+00:00, execution_date=20240602T185106, start_date=20240602T185114, end_date=20240602T185120
[2024-06-02T18:51:20.556+0000] {local_task_job_runner.py:240} INFO - Task exited with return code 0
[2024-06-02T18:51:20.573+0000] {taskinstance.py:3498} INFO - 0 downstream tasks scheduled from follow-on schedule check
[2024-06-02T18:51:20.574+0000] {local_task_job_runner.py:222} INFO - ::endgroup::
