[2024-06-02T15:46:21.962+0000] {local_task_job_runner.py:120} INFO - ::group::Pre task execution logs
[2024-06-02T15:46:21.984+0000] {taskinstance.py:2076} INFO - Dependencies all met for dep_context=non-requeueable deps ti=<TaskInstance: api_to_redshift.load_data_task manual__2024-06-02T15:46:12.014829+00:00 [queued]>
[2024-06-02T15:46:21.991+0000] {taskinstance.py:2076} INFO - Dependencies all met for dep_context=requeueable deps ti=<TaskInstance: api_to_redshift.load_data_task manual__2024-06-02T15:46:12.014829+00:00 [queued]>
[2024-06-02T15:46:21.992+0000] {taskinstance.py:2306} INFO - Starting attempt 1 of 1
[2024-06-02T15:46:22.002+0000] {taskinstance.py:2330} INFO - Executing <Task(BashOperator): load_data_task> on 2024-06-02 15:46:12.014829+00:00
[2024-06-02T15:46:22.010+0000] {warnings.py:110} WARNING - /home/***/.local/lib/python3.12/site-packages/***/task/task_runner/standard_task_runner.py:61: DeprecationWarning: This process (pid=103) is multi-threaded, use of fork() may lead to deadlocks in the child.
  pid = os.fork()

[2024-06-02T15:46:22.012+0000] {standard_task_runner.py:63} INFO - Started process 105 to run task
[2024-06-02T15:46:22.013+0000] {standard_task_runner.py:90} INFO - Running: ['***', 'tasks', 'run', 'api_to_redshift', 'load_data_task', 'manual__2024-06-02T15:46:12.014829+00:00', '--job-id', '287', '--raw', '--subdir', 'DAGS_FOLDER/get_data.py', '--cfg-path', '/tmp/tmp_ia3q0nq']
[2024-06-02T15:46:22.015+0000] {standard_task_runner.py:91} INFO - Job 287: Subtask load_data_task
[2024-06-02T15:46:22.088+0000] {task_command.py:426} INFO - Running <TaskInstance: api_to_redshift.load_data_task manual__2024-06-02T15:46:12.014829+00:00 [running]> on host 62b7d9571edd
[2024-06-02T15:46:22.182+0000] {taskinstance.py:2648} INFO - Exporting env vars: AIRFLOW_CTX_DAG_OWNER='Data Team' AIRFLOW_CTX_DAG_ID='api_to_redshift' AIRFLOW_CTX_TASK_ID='load_data_task' AIRFLOW_CTX_EXECUTION_DATE='2024-06-02T15:46:12.014829+00:00' AIRFLOW_CTX_TRY_NUMBER='1' AIRFLOW_CTX_DAG_RUN_ID='manual__2024-06-02T15:46:12.014829+00:00'
[2024-06-02T15:46:22.185+0000] {taskinstance.py:430} INFO - ::endgroup::
[2024-06-02T15:46:22.186+0000] {subprocess.py:63} INFO - Tmp dir root location: /tmp
[2024-06-02T15:46:22.188+0000] {subprocess.py:75} INFO - Running command: ['/usr/bin/bash', '-c', "curl 'http://s3-to-redshift-lambda:9500/2015-03-31/functions/function/invocations' -d '{}'"]
[2024-06-02T15:46:22.202+0000] {subprocess.py:86} INFO - Output:
[2024-06-02T15:46:22.217+0000] {subprocess.py:93} INFO -   % Total    % Received % Xferd  Average Speed   Time    Time     Time  Current
[2024-06-02T15:46:22.218+0000] {subprocess.py:93} INFO -                                  Dload  Upload   Total   Spent    Left  Speed
[2024-06-02T15:46:22.243+0000] {subprocess.py:93} INFO -   0     0    0     0    0     0      0      0 --:--:-- --:--:-- --:--:--     0curl: (6) Could not resolve host: s3-to-redshift-lambda
[2024-06-02T15:46:22.245+0000] {subprocess.py:97} INFO - Command exited with return code 6
[2024-06-02T15:46:22.246+0000] {taskinstance.py:441} INFO - ::group::Post task execution logs
[2024-06-02T15:46:22.264+0000] {taskinstance.py:2905} ERROR - Task failed with exception
Traceback (most recent call last):
  File "/home/airflow/.local/lib/python3.12/site-packages/airflow/models/taskinstance.py", line 465, in _execute_task
    result = _execute_callable(context=context, **execute_callable_kwargs)
             ^^^^^^^^^^^^^^^^^^^^^^^^^^^^^^^^^^^^^^^^^^^^^^^^^^^^^^^^^^^^^
  File "/home/airflow/.local/lib/python3.12/site-packages/airflow/models/taskinstance.py", line 432, in _execute_callable
    return execute_callable(context=context, **execute_callable_kwargs)
           ^^^^^^^^^^^^^^^^^^^^^^^^^^^^^^^^^^^^^^^^^^^^^^^^^^^^^^^^^^^^
  File "/home/airflow/.local/lib/python3.12/site-packages/airflow/models/baseoperator.py", line 400, in wrapper
    return func(self, *args, **kwargs)
           ^^^^^^^^^^^^^^^^^^^^^^^^^^^
  File "/home/airflow/.local/lib/python3.12/site-packages/airflow/operators/bash.py", line 243, in execute
    raise AirflowException(
airflow.exceptions.AirflowException: Bash command failed. The command returned a non-zero exit code 6.
[2024-06-02T15:46:22.271+0000] {taskinstance.py:1206} INFO - Marking task as FAILED. dag_id=api_to_redshift, task_id=load_data_task, run_id=manual__2024-06-02T15:46:12.014829+00:00, execution_date=20240602T154612, start_date=20240602T154621, end_date=20240602T154622
[2024-06-02T15:46:22.285+0000] {standard_task_runner.py:110} ERROR - Failed to execute job 287 for task load_data_task (Bash command failed. The command returned a non-zero exit code 6.; 105)
[2024-06-02T15:46:22.311+0000] {local_task_job_runner.py:240} INFO - Task exited with return code 1
[2024-06-02T15:46:22.338+0000] {taskinstance.py:3498} INFO - 0 downstream tasks scheduled from follow-on schedule check
[2024-06-02T15:46:22.343+0000] {local_task_job_runner.py:222} INFO - ::endgroup::
