[2024-06-02T09:13:40.425+0000] {local_task_job_runner.py:120} INFO - ::group::Pre task execution logs
[2024-06-02T09:13:40.436+0000] {taskinstance.py:2076} INFO - Dependencies all met for dep_context=non-requeueable deps ti=<TaskInstance: api_to_redshift.fetch_data_task manual__2024-06-02T09:13:38.104285+00:00 [queued]>
[2024-06-02T09:13:40.440+0000] {taskinstance.py:2076} INFO - Dependencies all met for dep_context=requeueable deps ti=<TaskInstance: api_to_redshift.fetch_data_task manual__2024-06-02T09:13:38.104285+00:00 [queued]>
[2024-06-02T09:13:40.441+0000] {taskinstance.py:2306} INFO - Starting attempt 1 of 1
[2024-06-02T09:13:40.448+0000] {taskinstance.py:2330} INFO - Executing <Task(BashOperator): fetch_data_task> on 2024-06-02 09:13:38.104285+00:00
[2024-06-02T09:13:40.453+0000] {warnings.py:110} WARNING - /home/***/.local/lib/python3.12/site-packages/***/task/task_runner/standard_task_runner.py:61: DeprecationWarning: This process (pid=1416) is multi-threaded, use of fork() may lead to deadlocks in the child.
  pid = os.fork()

[2024-06-02T09:13:40.455+0000] {standard_task_runner.py:63} INFO - Started process 1418 to run task
[2024-06-02T09:13:40.456+0000] {standard_task_runner.py:90} INFO - Running: ['***', 'tasks', 'run', 'api_to_redshift', 'fetch_data_task', 'manual__2024-06-02T09:13:38.104285+00:00', '--job-id', '126', '--raw', '--subdir', 'DAGS_FOLDER/get_data.py', '--cfg-path', '/tmp/tmpw2oqoies']
[2024-06-02T09:13:40.457+0000] {standard_task_runner.py:91} INFO - Job 126: Subtask fetch_data_task
[2024-06-02T09:13:40.497+0000] {task_command.py:426} INFO - Running <TaskInstance: api_to_redshift.fetch_data_task manual__2024-06-02T09:13:38.104285+00:00 [running]> on host e5491654e688
[2024-06-02T09:13:40.558+0000] {taskinstance.py:2648} INFO - Exporting env vars: AIRFLOW_CTX_DAG_OWNER='Data Team' AIRFLOW_CTX_DAG_ID='api_to_redshift' AIRFLOW_CTX_TASK_ID='fetch_data_task' AIRFLOW_CTX_EXECUTION_DATE='2024-06-02T09:13:38.104285+00:00' AIRFLOW_CTX_TRY_NUMBER='1' AIRFLOW_CTX_DAG_RUN_ID='manual__2024-06-02T09:13:38.104285+00:00'
[2024-06-02T09:13:40.560+0000] {taskinstance.py:430} INFO - ::endgroup::
[2024-06-02T09:13:40.561+0000] {subprocess.py:63} INFO - Tmp dir root location: /tmp
[2024-06-02T09:13:40.562+0000] {subprocess.py:75} INFO - Running command: ['/usr/bin/bash', '-c', "curl 'http://localhost:900093/2015-03-31/functions/function/invocations' -d '{}'"]
[2024-06-02T09:13:40.574+0000] {subprocess.py:86} INFO - Output:
[2024-06-02T09:13:40.586+0000] {subprocess.py:93} INFO - curl: (3) URL using bad/illegal format or missing URL
[2024-06-02T09:13:40.587+0000] {subprocess.py:97} INFO - Command exited with return code 3
[2024-06-02T09:13:40.587+0000] {taskinstance.py:441} INFO - ::group::Post task execution logs
[2024-06-02T09:13:40.597+0000] {taskinstance.py:2905} ERROR - Task failed with exception
Traceback (most recent call last):
  File "/home/airflow/.local/lib/python3.12/site-packages/airflow/models/taskinstance.py", line 465, in _execute_task
    result = _execute_callable(context=context, **execute_callable_kwargs)
             ^^^^^^^^^^^^^^^^^^^^^^^^^^^^^^^^^^^^^^^^^^^^^^^^^^^^^^^^^^^^^
  File "/home/airflow/.local/lib/python3.12/site-packages/airflow/models/taskinstance.py", line 432, in _execute_callable
    return execute_callable(context=context, **execute_callable_kwargs)
           ^^^^^^^^^^^^^^^^^^^^^^^^^^^^^^^^^^^^^^^^^^^^^^^^^^^^^^^^^^^^
  File "/home/airflow/.local/lib/python3.12/site-packages/airflow/models/baseoperator.py", line 400, in wrapper
    return func(self, *args, **kwargs)
           ^^^^^^^^^^^^^^^^^^^^^^^^^^^
  File "/home/airflow/.local/lib/python3.12/site-packages/airflow/operators/bash.py", line 243, in execute
    raise AirflowException(
airflow.exceptions.AirflowException: Bash command failed. The command returned a non-zero exit code 3.
[2024-06-02T09:13:40.600+0000] {taskinstance.py:1206} INFO - Marking task as FAILED. dag_id=api_to_redshift, task_id=fetch_data_task, run_id=manual__2024-06-02T09:13:38.104285+00:00, execution_date=20240602T091338, start_date=20240602T091340, end_date=20240602T091340
[2024-06-02T09:13:40.610+0000] {standard_task_runner.py:110} ERROR - Failed to execute job 126 for task fetch_data_task (Bash command failed. The command returned a non-zero exit code 3.; 1418)
[2024-06-02T09:13:40.628+0000] {local_task_job_runner.py:240} INFO - Task exited with return code 1
[2024-06-02T09:13:40.651+0000] {taskinstance.py:3498} INFO - 0 downstream tasks scheduled from follow-on schedule check
[2024-06-02T09:13:40.654+0000] {local_task_job_runner.py:222} INFO - ::endgroup::
